Workbook

Sheet Dashboard
B1: E-COMMERCE SALES & CUSTOMER INSIGHTS DASHBOARD
B2: Data period: Jan 2023 - Dec 2025 | All figures in INR (Rs.)
B4: Total Revenue (Rs.) | D4: Total Orders | F4: Total Customers | H4: Avg Order Value (Rs.) | J4: Cancellation + Return Rate | L4: Customer Churn Rate (90+ days)
B5: =SUMIFS(Orders!$H:$H,Orders!$D:$D,"Delivered") -> 1.1738694e+08 | D5: =COUNTIFS(Orders!$D:$D,"Delivered") -> 4625 | F5: =COUNTA(Customers!$A$2:$A$1201) -> 1200 | H5: =IFERROR(B5/D5,0) -> 25380.961 | J5: =(COUNTIF(Orders!$D:$D,"Cancelled")+COUNTIF(Orders!$D:$D,"Returned"))/COUNTA(Orders!$A$2:$A$5316) -> 0.12982126 | L5: =COUNTIF(Customers!$Q:$Q,1)/COUNTA(Customers!$A$2:$A$1201) -> 0.46583333

Sheet Summary
A1: E-COMMERCE SALES & CUSTOMER INSIGHTS -- SUMMARY TABLES
A2: Every figure below is a live Excel formula (SUMIFS / COUNTIFS / INDEX-MATCH) referencing the raw data sheets.
A4: Monthly Revenue Trend
A5: Month | B5: Orders | C5: Revenue | D5: Avg Order Value
A6: 2023-01 | B6: =COUNTIFS(Orders!$D:$D,"Delivered",Orders!$I:$I,A6) -> 4 | C6: =SUMIFS(Orders!$H:$H,Orders!$D:$D,"Delivered",Orders!$I:$I,A6) -> 107881.45 | D6: =IFERROR(C6/B6,0) -> 26970.362
A7: 2023-02 | B7: =COUNTIFS(Orders!$D:$D,"Delivered",Orders!$I:$I,A7) -> 4 | C7: =SUMIFS(Orders!$H:$H,Orders!$D:$D,"Delivered",Orders!$I:$I,A7) -> 86195.4 | D7: =IFERROR(C7/B7,0) -> 21548.85
A8: 2023-03 | B8: =COUNTIFS(Orders!$D:$D,"Delivered",Orders!$I:$I,A8) -> 10 | C8: =SUMIFS(Orders!$H:$H,Orders!$D:$D,"Delivered",Orders!$I:$I,A8) -> 129899.7 | D8: =IFERROR(C8/B8,0) -> 12989.97
A9: 2023-04 | B9: =COUNTIFS(Orders!$D:$D,"Delivered",Orders!$I:$I,A9) -> 13 | C9: =SUMIFS(Orders!$H:$H,Orders!$D:$D,"Delivered",Orders!$I:$I,A9) -> 399449.7 | D9: =IFERROR(C9/B9,0) -> 30726.9
A10: 2023-05 | B10: =COUNTIFS(Orders!$D:$D,"Delivered",Orders!$I:$I,A10) -> 10 | C10: =SUMIFS(Orders!$H:$H,Orders!$D:$D,"Delivered",Orders!$I:$I,A10) -> 328505 | D10: =IFERROR(C10/B10,0) -> 32850.5
A11: 2023-06 | B11: =COUNTIFS(Orders!$D:$D,"Delivered",Orders!$I:$I,A11) -> 25 | C11: =SUMIFS(Orders!$H:$H,Orders!$D:$D,"Delivered",Orders!$I:$I,A11) -> 740881.1 | D11: =IFERROR(C11/B11,0) -> 29635.244
A12: 2023-07 | B12: =COUNTIFS(Orders!$D:$D,"Delivered",Orders!$I:$I,A12) -> 16 | C12: =SUMIFS(Orders!$H:$H,Orders!$D:$D,"Delivered",Orders!$I:$I,A12) -> 402496.4 | D12: =IFERROR(C12/B12,0) -> 25156.025
A13: 2023-08 | B13: =COUNTIFS(Orders!$D:$D,"Delivered",Orders!$I:$I,A13) -> 48 | C13: =SUMIFS(Orders!$H:$H,Orders!$D:$D,"Delivered",Orders!$I:$I,A13) -> 1162983.2 | D13: =IFERROR(C13/B13,0) -> 24228.818
A14: 2023-09 | B14: =COUNTIFS(Orders!$D:$D,"Delivered",Orders!$I:$I,A14) -> 26 | C14: =SUMIFS(Orders!$H:$H,Orders!$D:$D,"Delivered",Orders!$I:$I,A14) -> 684686.8 | D14: =IFERROR(C14/B14,0) -> 26334.108
A15: 2023-10 | B15: =COUNTIFS(Orders!$D:$D,"Delivered",Orders!$I:$I,A15) -> 83 | C15: =SUMIFS(Orders!$H:$H,Orders!$D:$D,"Delivered",Orders!$I:$I,A15) -> 2140158.7 | D15: =IFERROR(C15/B15,0) -> 25785.045
A16: 2023-11 | B16: =COUNTIFS(Orders!$D:$D,"Delivered",Orders!$I:$I,A16) -> 68 | C16: =SUMIFS(Orders!$H:$H,Orders!$D:$D,"Delivered",Orders!$I:$I,A16) -> 2047297.3 | D16: =IFERROR(C16/B16,0) -> 30107.313
A17: 2023-12 | B17: =COUNTIFS(Orders!$D:$D,"Delivered",Orders!$I:$I,A17) -> 38 | C17: =SUMIFS(Orders!$H:$H,Orders!$D:$D,"Delivered",Orders!$I:$I,A17) -> 1034273.3 | D17: =IFERROR(C17/B17,0) -> 27217.718
... A41: 2025-12 | B41: =COUNTIFS(Orders!$D:$D,"Delivered",Orders!$I:$I,A41) -> 361 | C41: =SUMIFS(Orders!$H:$H,Orders!$D:$D,"Delivered",Orders!$I:$I,A41) -> 9367211.8 | D41: =IFERROR(C41/B41,0) -> 25947.955
A44: Revenue & Margin by Category
A45: Category | B45: Units Sold | C45: Revenue | D45: Cost | E45: Profit | F45: Margin %
A46: Electronics | B46: =SUMIFS(OrderItems!$D:$D,OrderItems!$H:$H,A46,OrderItems!$I:$I,"Delivered") -> 2027 | C46: =SUMIFS(OrderItems!$G:$G,OrderItems!$H:$H,A46,OrderItems!$I:$I,"Delivered") -> 43354167 | D46: =SUMIFS(OrderItems!$K:$K,OrderItems!$H:$H,A46,OrderItems!$I:$I,"Delivered") -> 31261343 | E46: =C46-D46 -> 12092824 | F46: =IFERROR(E46/C46,0) -> 0.27893107
A47: Mobiles & Accessories | B47: =SUMIFS(OrderItems!$D:$D,OrderItems!$H:$H,A47,OrderItems!$I:$I,"Delivered") -> 1100 | C47: =SUMIFS(OrderItems!$G:$G,OrderItems!$H:$H,A47,OrderItems!$I:$I,"Delivered") -> 39277378 | D47: =SUMIFS(OrderItems!$K:$K,OrderItems!$H:$H,A47,OrderItems!$I:$I,"Delivered") -> 26889668 | E47: =C47-D47 -> 12387710 | F47: =IFERROR(E47/C47,0) -> 0.31539045
A48: Home & Kitchen | B48: =SUMIFS(OrderItems!$D:$D,OrderItems!$H:$H,A48,OrderItems!$I:$I,"Delivered") -> 1602 | C48: =SUMIFS(OrderItems!$G:$G,OrderItems!$H:$H,A48,OrderItems!$I:$I,"Delivered") -> 13721546 | D48: =SUMIFS(OrderItems!$K:$K,OrderItems!$H:$H,A48,OrderItems!$I:$I,"Delivered") -> 9474101.6 | E48: =C48-D48 -> 4247444 | F48: =IFERROR(E48/C48,0) -> 0.30954559
A49: Furniture | B49: =SUMIFS(OrderItems!$D:$D,OrderItems!$H:$H,A49,OrderItems!$I:$I,"Delivered") -> 466 | C49: =SUMIFS(OrderItems!$G:$G,OrderItems!$H:$H,A49,OrderItems!$I:$I,"Delivered") -> 9198399.8 | D49: =SUMIFS(OrderItems!$K:$K,OrderItems!$H:$H,A49,OrderItems!$I:$I,"Delivered") -> 6147152.6 | E49: =C49-D49 -> 3051247.2 | F49: =IFERROR(E49/C49,0) -> 0.331715
A50: Fashion | B50: =SUMIFS(OrderItems!$D:$D,OrderItems!$H:$H,A50,OrderItems!$I:$I,"Delivered") -> 2093 | C50: =SUMIFS(OrderItems!$G:$G,OrderItems!$H:$H,A50,OrderItems!$I:$I,"Delivered") -> 5181859.4 | D50: =SUMIFS(OrderItems!$K:$K,OrderItems!$H:$H,A50,OrderItems!$I:$I,"Delivered") -> 3722362.7 | E50: =C50-D50 -> 1459496.7 | F50: =IFERROR(E50/C50,0) -> 0.28165501
A51: Sports & Fitness | B51: =SUMIFS(OrderItems!$D:$D,OrderItems!$H:$H,A51,OrderItems!$I:$I,"Delivered") -> 669 | C51: =SUMIFS(OrderItems!$G:$G,OrderItems!$H:$H,A51,OrderItems!$I:$I,"Delivered") -> 3743722.4 | D51: =SUMIFS(OrderItems!$K:$K,OrderItems!$H:$H,A51,OrderItems!$I:$I,"Delivered") -> 2606396.1 | E51: =C51-D51 -> 1137326.3 | F51: =IFERROR(E51/C51,0) -> 0.30379557
A52: Beauty & Personal Care | B52: =SUMIFS(OrderItems!$D:$D,OrderItems!$H:$H,A52,OrderItems!$I:$I,"Delivered") -> 954 | C52: =SUMIFS(OrderItems!$G:$G,OrderItems!$H:$H,A52,OrderItems!$I:$I,"Delivered") -> 1410829.8 | D52: =SUMIFS(OrderItems!$K:$K,OrderItems!$H:$H,A52,OrderItems!$I:$I,"Delivered") -> 966618.58 | E52: =C52-D52 -> 444211.17 | F52: =IFERROR(E52/C52,0) -> 0.3148581
A53: Grocery | B53: =SUMIFS(OrderItems!$D:$D,OrderItems!$H:$H,A53,OrderItems!$I:$I,"Delivered") -> 672 | C53: =SUMIFS(OrderItems!$G:$G,OrderItems!$H:$H,A53,OrderItems!$I:$I,"Delivered") -> 516335.9 | D53: =SUMIFS(OrderItems!$K:$K,OrderItems!$H:$H,A53,OrderItems!$I:$I,"Delivered") -> 363018.08 | E53: =C53-D53 -> 153317.82 | F53: =IFERROR(E53/C53,0) -> 0.29693426
A54: Books | B54: =SUMIFS(OrderItems!$D:$D,OrderItems!$H:$H,A54,OrderItems!$I:$I,"Delivered") -> 484 | C54: =SUMIFS(OrderItems!$G:$G,OrderItems!$H:$H,A54,OrderItems!$I:$I,"Delivered") -> 400480.9 | D54: =SUMIFS(OrderItems!$K:$K,OrderItems!$H:$H,A54,OrderItems!$I:$I,"Delivered") -> 274812.05 | E54: =C54-D54 -> 125668.85 | F54: =IFERROR(E54/C54,0) -> 0.31379487
A55: Toys & Baby Care | B55: =SUMIFS(OrderItems!$D:$D,OrderItems!$H:$H,A55,OrderItems!$I:$I,"Delivered") -> 169 | C55: =SUMIFS(OrderItems!$G:$G,OrderItems!$H:$H,A55,OrderItems!$I:$I,"Delivered") -> 432315.35 | D55: =SUMIFS(OrderItems!$K:$K,OrderItems!$H:$H,A55,OrderItems!$I:$I,"Delivered") -> 293910.26 | E55: =C55-D55 -> 138405.09 | F55: =IFERROR(E55/C55,0) -> 0.32014845
A58: Top 10 Products by Revenue
A59: Rank | B59: Product Name | C59: Category | D59: Revenue
A60: 1 | B60: =INDEX(Products!$B:$B,MATCH(A60,Products!$H:$H,0)) -> USB-C Cable - Tan | C60: =INDEX(Products!$C:$C,MATCH(A60,Products!$H:$H,0)) -> Mobiles & Accessories | D60: =INDEX(Products!$G:$G,MATCH(A60,Products!$H:$H,0)) -> 4460126.6
A61: 2 | B61: =INDEX(Products!$B:$B,MATCH(A61,Products!$H:$H,0)) -> Selfie Stick | C61: =INDEX(Products!$C:$C,MATCH(A61,Products!$H:$H,0)) -> Mobiles & Accessories | D61: =INDEX(Products!$G:$G,MATCH(A61,Products!$H:$H,0)) -> 4188256
A62: 3 | B62: =INDEX(Products!$B:$B,MATCH(A62,Products!$H:$H,0)) -> Smartphone 5G - SpringGreen | C62: =INDEX(Products!$C:$C,MATCH(A62,Products!$H:$H,0)) -> Mobiles & Accessories | D62: =INDEX(Products!$G:$G,MATCH(A62,Products!$H:$H,0)) -> 3905320.2
A63: 4 | B63: =INDEX(Products!$B:$B,MATCH(A63,Products!$H:$H,0)) -> Phone Holder | C63: =INDEX(Products!$C:$C,MATCH(A63,Products!$H:$H,0)) -> Mobiles & Accessories | D63: =INDEX(Products!$G:$G,MATCH(A63,Products!$H:$H,0)) -> 3738016
A64: 5 | B64: =INDEX(Products!$B:$B,MATCH(A64,Products!$H:$H,0)) -> USB-C Cable | C64: =INDEX(Products!$C:$C,MATCH(A64,Products!$H:$H,0)) -> Mobiles & Accessories | D64: =INDEX(Products!$G:$G,MATCH(A64,Products!$H:$H,0)) -> 3553601.9
A65: 6 | B65: =INDEX(Products!$B:$B,MATCH(A65,Products!$H:$H,0)) -> Wireless Charger - AliceBlue | C65: =INDEX(Products!$C:$C,MATCH(A65,Products!$H:$H,0)) -> Mobiles & Accessories | D65: =INDEX(Products!$G:$G,MATCH(A65,Products!$H:$H,0)) -> 3536721.5
A66: 7 | B66: =INDEX(Products!$B:$B,MATCH(A66,Products!$H:$H,0)) -> Home Theatre System | C66: =INDEX(Products!$C:$C,MATCH(A66,Products!$H:$H,0)) -> Electronics | D66: =INDEX(Products!$G:$G,MATCH(A66,Products!$H:$H,0)) -> 2849204.1
A67: 8 | B67: =INDEX(Products!$B:$B,MATCH(A67,Products!$H:$H,0)) -> Phone Holder | C67: =INDEX(Products!$C:$C,MATCH(A67,Products!$H:$H,0)) -> Mobiles & Accessories | D67: =INDEX(Products!$G:$G,MATCH(A67,Products!$H:$H,0)) -> 2539831.8
A68: 9 | B68: =INDEX(Products!$B:$B,MATCH(A68,Products!$H:$H,0)) -> Bluetooth Speaker | C68: =INDEX(Products!$C:$C,MATCH(A68,Products!$H:$H,0)) -> Electronics | D68: =INDEX(Products!$G:$G,MATCH(A68,Products!$H:$H,0)) -> 2314827.8
...

Sheet Orders
A1: order_id | B1: customer_id | C1: order_date | D1: order_status | E1: payment_method | F1: shipping_city | G1: shipping_state | H1: order_total | I1: order_month | J1: acquisition_channel
A2: ORD000001 | B2: CUST00001 | C2: 2024-10-14 | D2: Delivered | E2: Net Banking | F2: Hyderabad | G2: Telangana | H2: 1640 | I2: =TEXT(C2,"YYYY-MM") -> 2024-10 | J2: =INDEX(Customers!$H:$H,MATCH(B2,Customers!$A:$A,0)) -> Organic Search
A3: ORD000002 | B3: CUST00002 | C3: 2023-08-31 | D3: Delivered | E3: UPI | F3: Chennai | G3: Tamil Nadu | H3: 20670.3 | I3: =TEXT(C3,"YYYY-MM") -> 2023-08 | J3: =INDEX(Customers!$H:$H,MATCH(B3,Customers!$A:$A,0)) -> Social Media
A4: ORD000003 | B4: CUST00002 | C4: 2025-11-14 | D4: Delivered | E4: Wallet | F4: Chennai | G4: Tamil Nadu | H4: 8855.15 | I4: =TEXT(C4,"YYYY-MM") -> 2025-11 | J4: =INDEX(Customers!$H:$H,MATCH(B4,Customers!$A:$A,0)) -> Social Media
A5: ORD000004 | B5: CUST00003 | C5: 2023-07-20 | D5: Delivered | E5: Wallet | F5: Delhi | G5: Delhi | H5: 4138.65 | I5: =TEXT(C5,"YYYY-MM") -> 2023-07 | J5: =INDEX(Customers!$H:$H,MATCH(B5,Customers!$A:$A,0)) -> Organic Search
A6: ORD000005 | B6: CUST00003 | C6: 2023-09-04 | D6: Delivered | E6: Cash on Delivery | F6: Delhi | G6: Delhi | H6: 89603.35 | I6: =TEXT(C6,"YYYY-MM") -> 2023-09 | J6: =INDEX(Customers!$H:$H,MATCH(B6,Customers!$A:$A,0)) -> Organic Search
A7: ORD000006 | B7: CUST00003 | C7: 2023-11-29 | D7: Delivered | E7: Credit Card | F7: Delhi | G7: Delhi | H7: 7919 | I7: =TEXT(C7,"YYYY-MM") -> 2023-11 | J7: =INDEX(Customers!$H:$H,MATCH(B7,Customers!$A:$A,0)) -> Organic Search
A8: ORD000007 | B8: CUST00003 | C8: 2023-12-05 | D8: Delivered | E8: Cash on Delivery | F8: Delhi | G8: Delhi | H8: 56352.2 | I8: =TEXT(C8,"YYYY-MM") -> 2023-12 | J8: =INDEX(Customers!$H:$H,MATCH(B8,Customers!$A:$A,0)) -> Organic Search
A9: ORD000008 | B9: CUST00003 | C9: 2023-12-29 | D9: Delivered | E9: Credit Card | F9: Delhi | G9: Delhi | H9: 1546.3 | I9: =TEXT(C9,"YYYY-MM") -> 2023-12 | J9: =INDEX(Customers!$H:$H,MATCH(B9,Customers!$A:$A,0)) -> Organic Search
A10: ORD000009 | B10: CUST00003 | C10: 2024-02-21 | D10: Delivered | E10: Cash on Delivery | F10: Delhi | G10: Delhi | H10: 1630.3 | I10: =TEXT(C10,"YYYY-MM") -> 2024-02 | J10: =INDEX(Customers!$H:$H,MATCH(B10,Customers!$A:$A,0)) -> Organic Search
A11: ORD000010 | B11: CUST00003 | C11: 2024-04-07 | D11: Delivered | E11: Debit Card | F11: Delhi | G11: Delhi | H11: 23049 | I11: =TEXT(C11,"YYYY-MM") -> 2024-04 | J11: =INDEX(Customers!$H:$H,MATCH(B11,Customers!$A:$A,0)) -> Organic Search
A12: ORD000011 | B12: CUST00003 | C12: 2024-05-09 | D12: Delivered | E12: Net Banking | F12: Delhi | G12: Delhi | H12: 17864.1 | I12: =TEXT(C12,"YYYY-MM") -> 2024-05 | J12: =INDEX(Customers!$H:$H,MATCH(B12,Customers!$A:$A,0)) -> Organic Search
A13: ORD000012 | B13: CUST00003 | C13: 2024-07-23 | D13: Cancelled | E13: Debit Card | F13: Delhi | G13: Delhi | H13: 6983.2 | I13: =TEXT(C13,"YYYY-MM") -> 2024-07 | J13: =INDEX(Customers!$H:$H,MATCH(B13,Customers!$A:$A,0)) -> Organic Search
... A5316: ORD005315 | B5316: CUST01200 | C5316: 2025-11-30 | D5316: Delivered | E5316: Wallet | F5316: Kolkata | G5316: West Bengal | H5316: 315 | I5316: =TEXT(C5316,"YYYY-MM") -> 2025-11 | J5316: =INDEX(Customers!$H:$H,MATCH(B5316,Customers!$A:$A,0)) -> Referral

Sheet OrderItems
A1: order_item_id | B1: order_id | C1: product_id | D1: quantity | E1: unit_price | F1: discount_pct | G1: line_total | H1: category | I1: order_status | J1: unit_cost | K1: line_cost
A2: OI0000001 | B2: ORD000001 | C2: PROD0155 | D2: 1 | E2: 1640 | F2: 0 | G2: 1640 | H2: =INDEX(Products!$C:$C,MATCH(C2,Products!$A:$A,0)) -> Beauty & Personal Care | I2: =INDEX(Orders!$D:$D,MATCH(B2,Orders!$A:$A,0)) -> Delivered | J2: =INDEX(Products!$E:$E,MATCH(C2,Products!$A:$A,0)) -> 939.85 | K2: =D2*J2 -> 939.85
A3: OI0000002 | B3: ORD000002 | C3: PROD0074 | D3: 2 | E3: 12159 | F3: 15 | G3: 20670.3 | H3: =INDEX(Products!$C:$C,MATCH(C3,Products!$A:$A,0)) -> Mobiles & Accessories | I3: =INDEX(Orders!$D:$D,MATCH(B3,Orders!$A:$A,0)) -> Delivered | J3: =INDEX(Products!$E:$E,MATCH(C3,Products!$A:$A,0)) -> 8791.68 | K3: =D3*J3 -> 17583.36
A4: OI0000003 | B4: ORD000003 | C4: PROD0007 | D4: 1 | E4: 8040 | F4: 0 | G4: 8040 | H4: =INDEX(Products!$C:$C,MATCH(C4,Products!$A:$A,0)) -> Home & Kitchen | I4: =INDEX(Orders!$D:$D,MATCH(B4,Orders!$A:$A,0)) -> Delivered | J4: =INDEX(Products!$E:$E,MATCH(C4,Products!$A:$A,0)) -> 4810.96 | K4: =D4*J4 -> 4810.96
A5: OI0000004 | B5: ORD000003 | C5: PROD0005 | D5: 1 | E5: 959 | F5: 15 | G5: 815.15 | H5: =INDEX(Products!$C:$C,MATCH(C5,Products!$A:$A,0)) -> Toys & Baby Care | I5: =INDEX(Orders!$D:$D,MATCH(B5,Orders!$A:$A,0)) -> Delivered | J5: =INDEX(Products!$E:$E,MATCH(C5,Products!$A:$A,0)) -> 528.95 | K5: =D5*J5 -> 528.95
A6: OI0000005 | B6: ORD000004 | C6: PROD0117 | D6: 1 | E6: 4869 | F6: 15 | G6: 4138.65 | H6: =INDEX(Products!$C:$C,MATCH(C6,Products!$A:$A,0)) -> Fashion | I6: =INDEX(Orders!$D:$D,MATCH(B6,Orders!$A:$A,0)) -> Delivered | J6: =INDEX(Products!$E:$E,MATCH(C6,Products!$A:$A,0)) -> 3494.47 | K6: =D6*J6 -> 3494.47
A7: OI0000006 | B7: ORD000005 | C7: PROD0066 | D7: 3 | E7: 25819 | F7: 10 | G7: 69711.3 | H7: =INDEX(Products!$C:$C,MATCH(C7,Products!$A:$A,0)) -> Furniture | I7: =INDEX(Orders!$D:$D,MATCH(B7,Orders!$A:$A,0)) -> Delivered | J7: =INDEX(Products!$E:$E,MATCH(C7,Products!$A:$A,0)) -> 17102.88 | K7: =D7*J7 -> 51308.64
A8: OI0000007 | B8: ORD000005 | C8: PROD0144 | D8: 1 | E8: 20939 | F8: 5 | G8: 19892.05 | H8: =INDEX(Products!$C:$C,MATCH(C8,Products!$A:$A,0)) -> Mobiles & Accessories | I8: =INDEX(Orders!$D:$D,MATCH(B8,Orders!$A:$A,0)) -> Delivered | J8: =INDEX(Products!$E:$E,MATCH(C8,Products!$A:$A,0)) -> 12008.73 | K8: =D8*J8 -> 12008.73
A9: OI0000008 | B9: ORD000006 | C9: PROD0146 | D9: 1 | E9: 7919 | F9: 0 | G9: 7919 | H9: =INDEX(Products!$C:$C,MATCH(C9,Products!$A:$A,0)) -> Home & Kitchen | I9: =INDEX(Orders!$D:$D,MATCH(B9,Orders!$A:$A,0)) -> Delivered | J9: =INDEX(Products!$E:$E,MATCH(C9,Products!$A:$A,0)) -> 4611.02 | K9: =D9*J9 -> 4611.02
A10: OI0000009 | B10: ORD000007 | C10: PROD0050 | D10: 1 | E10: 26229 | F10: 20 | G10: 20983.2 | H10: =INDEX(Products!$C:$C,MATCH(C10,Products!$A:$A,0)) -> Furniture | I10: =INDEX(Orders!$D:$D,MATCH(B10,Orders!$A:$A,0)) -> Delivered | J10: =INDEX(Products!$E:$E,MATCH(C10,Products!$A:$A,0)) -> 18876.62 | K10: =D10*J10 -> 18876.62
A11: OI0000010 | B11: ORD000007 | C11: PROD0178 | D11: 1 | E11: 35369 | F11: 0 | G11: 35369 | H11: =INDEX(Products!$C:$C,MATCH(C11,Products!$A:$A,0)) -> Electronics | I11: =INDEX(Orders!$D:$D,MATCH(B11,Orders!$A:$A,0)) -> Delivered | J11: =INDEX(Products!$E:$E,MATCH(C11,Products!$A:$A,0)) -> 24770.66 | K11: =D11*J11 -> 24770.66
A12: OI0000011 | B12: ORD000008 | C12: PROD0157 | D12: 1 | E12: 2209 | F12: 30 | G12: 1546.3 | H12: =INDEX(Products!$C:$C,MATCH(C12,Products!$A:$A,0)) -> Beauty & Personal Care | I12: =INDEX(Orders!$D:$D,MATCH(B12,Orders!$A:$A,0)) -> Delivered | J12: =INDEX(Products!$E:$E,MATCH(C12,Products!$A:$A,0)) -> 1306.07 | K12: =D12*J12 -> 1306.07
A13: OI0000012 | B13: ORD000009 | C13: PROD0005 | D13: 2 | E13: 959 | F13: 15 | G13: 1630.3 | H13: =INDEX(Products!$C:$C,MATCH(C13,Products!$A:$A,0)) -> Toys & Baby Care | I13: =INDEX(Orders!$D:$D,MATCH(B13,Orders!$A:$A,0)) -> Delivered | J13: =INDEX(Products!$E:$E,MATCH(C13,Products!$A:$A,0)) -> 528.95 | K13: =D13*J13 -> 1057.9
... A9035: OI0009044 | B9035: ORD005315 | C9035: PROD0077 | D9035: 1 | E9035: 450 | F9035: 30 | G9035: 315 | H9035: =INDEX(Products!$C:$C,MATCH(C9035,Products!$A:$A,0)) -> Books | I9035: =INDEX(Orders!$D:$D,MATCH(B9035,Orders!$A:$A,0)) -> Delivered | J9035: =INDEX(Products!$E:$E,MATCH(C9035,Products!$A:$A,0)) -> 303.74 | K9035: =D9035*J9035 -> 303.74

Sheet Products
A1: product_id | B1: product_name | C1: category | D1: unit_price | E1: unit_cost | F1: rating | G1: total_revenue | H1: revenue_rank
A2: PROD0001 | B2: Dinner Set | C2: Home & Kitchen | D2: 12200 | E2: 8261.73 | F2: 4.8 | G2: =SUMIFS(OrderItems!$G:$G,OrderItems!$C:$C,A2,OrderItems!$I:$I,"Delivered") -> 614270 | H2: =RANK(G2,$G$2:$G$181,0)+COUNTIF($G$2:G2,G2)-1 -> 59
A3: PROD0002 | B3: Bluetooth Neckband | C3: Mobiles & Accessories | D3: 23659 | E3: 14645.83 | F3: 3.5 | G3: =SUMIFS(OrderItems!$G:$G,OrderItems!$C:$C,A3,OrderItems!$I:$I,"Delivered") -> 1027983.6 | H3: =RANK(G3,$G$2:$G$181,0)+COUNTIF($G$2:G3,G3)-1 -> 40
A4: PROD0003 | B4: Women's Handbag | C4: Fashion | D4: 4659 | E4: 2833.14 | F4: 4.5 | G4: =SUMIFS(OrderItems!$G:$G,OrderItems!$C:$C,A4,OrderItems!$I:$I,"Delivered") -> 217109.4 | H4: =RANK(G4,$G$2:$G$181,0)+COUNTIF($G$2:G4,G4)-1 -> 95
A5: PROD0004 | B5: Formal Shirt | C5: Fashion | D5: 3729 | E5: 2097.34 | F5: 4 | G5: =SUMIFS(OrderItems!$G:$G,OrderItems!$C:$C,A5,OrderItems!$I:$I,"Delivered") -> 177873.3 | H5: =RANK(G5,$G$2:$G$181,0)+COUNTIF($G$2:G5,G5)-1 -> 107
A6: PROD0005 | B6: Stroller | C6: Toys & Baby Care | D6: 959 | E6: 528.95 | F6: 3.6 | G6: =SUMIFS(OrderItems!$G:$G,OrderItems!$C:$C,A6,OrderItems!$I:$I,"Delivered") -> 46799.2 | H6: =RANK(G6,$G$2:$G$181,0)+COUNTIF($G$2:G6,G6)-1 -> 159
A7: PROD0006 | B7: Casual Sneakers - Snow | C7: Fashion | D7: 1029 | E7: 763.09 | F7: 5 | G7: =SUMIFS(OrderItems!$G:$G,OrderItems!$C:$C,A7,OrderItems!$I:$I,"Delivered") -> 60247.95 | H7: =RANK(G7,$G$2:$G$181,0)+COUNTIF($G$2:G7,G7)-1 -> 152
A8: PROD0007 | B8: Mixer Grinder | C8: Home & Kitchen | D8: 8040 | E8: 4810.96 | F8: 5 | G8: =SUMIFS(OrderItems!$G:$G,OrderItems!$C:$C,A8,OrderItems!$I:$I,"Delivered") -> 428130 | H8: =RANK(G8,$G$2:$G$181,0)+COUNTIF($G$2:G8,G8)-1 -> 75
A9: PROD0008 | B9: Phone Holder | C9: Mobiles & Accessories | D9: 7140 | E9: 4319.28 | F9: 4 | G9: =SUMIFS(OrderItems!$G:$G,OrderItems!$C:$C,A9,OrderItems!$I:$I,"Delivered") -> 298452 | H9: =RANK(G9,$G$2:$G$181,0)+COUNTIF($G$2:G9,G9)-1 -> 86
A10: PROD0009 | B10: Wireless Earbuds | C10: Electronics | D10: 36479 | E10: 23417.07 | F10: 2.9 | G10: =SUMIFS(OrderItems!$G:$G,OrderItems!$C:$C,A10,OrderItems!$I:$I,"Delivered") -> 2103014.4 | H10: =RANK(G10,$G$2:$G$181,0)+COUNTIF($G$2:G10,G10)-1 -> 13
A11: PROD0010 | B11: Non-Stick Cookware Set | C11: Home & Kitchen | D11: 949 | E11: 553.41 | F11: 4.8 | G11: =SUMIFS(OrderItems!$G:$G,OrderItems!$C:$C,A11,OrderItems!$I:$I,"Delivered") -> 51151.1 | H11: =RANK(G11,$G$2:$G$181,0)+COUNTIF($G$2:G11,G11)-1 -> 154
A12: PROD0011 | B12: Smartphone 5G | C12: Mobiles & Accessories | D12: 40359 | E12: 23885.95 | F12: 3.8 | G12: =SUMIFS(OrderItems!$G:$G,OrderItems!$C:$C,A12,OrderItems!$I:$I,"Delivered") -> 2314588.6 | H12: =RANK(G12,$G$2:$G$181,0)+COUNTIF($G$2:G12,G12)-1 -> 10
A13: PROD0012 | B13: Dining Table Set | C13: Furniture | D13: 33759 | E13: 19897.05 | F13: 4.3 | G13: =SUMIFS(OrderItems!$G:$G,OrderItems!$C:$C,A13,OrderItems!$I:$I,"Delivered") -> 1797666.8 | H13: =RANK(G13,$G$2:$G$181,0)+COUNTIF($G$2:G13,G13)-1 -> 17
... A181: PROD0180 | B181: Atta 5kg | C181: Grocery | D181: 1309 | E181: 914.27 | F181: 3.6 | G181: =SUMIFS(OrderItems!$G:$G,OrderItems!$C:$C,A181,OrderItems!$I:$I,"Delivered") -> 74809.35 | H181: =RANK(G181,$G$2:$G$181,0)+COUNTIF($G$2:G181,G181)-1 -> 146

Sheet Customers
A1: customer_id | B1: customer_name | C1: gender | D1: age | E1: city | F1: state | G1: signup_date | H1: acquisition_channel | I1: recency_days | J1: frequency | K1: monetary | L1: R_score | M1: F_score | N1: M_score | O1: RFM_score | P1: segment | Q1: is_churned | R1: cluster_label
A2: CUST00001 | B2: Advik Maharaj | C2: Male | D2: 36 | E2: Hyderabad | F2: Telangana | G2: 2024-07-17 | H2: Organic Search | I2: 444 | J2: 1 | K2: 1640 | L2: 5 | M2: 4 | N2: 5 | O2: 545 | P2: Champions | Q2: 1 | R2: Cluster C - Low Value
A3: CUST00002 | B3: Isaac Dewan | C3: Male | D3: 30 | E3: Chennai | F3: Tamil Nadu | G3: 2023-06-28 | H3: Social Media | I3: 48 | J3: 2 | K3: 29525.45 | L3: 2 | M3: 3 | N3: 4 | O3: 234 | P3: Potential Loyalist | Q3: 0 | R3: Cluster B - Mid Value
A4: CUST00003 | B4: Caleb Sami | C4: Male | D4: 37 | E4: Delhi | F4: Delhi | G4: 2023-07-11 | H4: Organic Search | I4: 71 | J4: 17 | K4: 424365.9 | L4: 3 | M4: 1 | N4: 1 | O4: 311 | P4: Needs Attention | Q4: 0 | R4: Cluster A - High Value
A5: CUST00004 | B5: Alexander Chander | C5: Male | D5: 45 | E5: Bhopal | F5: Madhya Pradesh | G5: 2024-02-12 | H5: Referral | I5: 123 | J5: 4 | K5: 8942.5 | L5: 3 | M5: 2 | N5: 5 | O5: 325 | P5: Needs Attention | Q5: 1 | R5: Cluster B - Mid Value
A6: CUST00005 | B6: Kamala Tiwari | C6: Female | D6: 29 | E6: Patna | F6: Bihar | G6: 2024-03-27 | H6: Paid Ads | I6: 43 | J6: 7 | K6: 187875.7 | L6: 2 | M6: 1 | N6: 1 | O6: 211 | P6: Lost / Churned | Q6: 0 | R6: Cluster A - High Value
A7: CUST00006 | B7: Hardik Saini | C7: Male | D7: 29 | E7: Jaipur | F7: Rajasthan | G7: 2023-11-23 | H7: Referral | I7: 203 | J7: 6 | K7: 124171.8 | L7: 4 | M7: 1 | N7: 2 | O7: 412 | P7: New / Promising | Q7: 1 | R7: Cluster A - High Value
A8: CUST00007 | B8: Vanya Mall | C8: Female | D8: 46 | E8: Surat | F8: Gujarat | G8: 2023-11-15 | H8: Organic Search | I8: 695 | J8: 1 | K8: 1971.15 | L8: 5 | M8: 4 | N8: 5 | O8: 545 | P8: Champions | Q8: 1 | R8: Cluster C - Low Value
A9: CUST00008 | B9: Fariq Sami | C9: Male | D9: 38 | E9: Surat | F9: Gujarat | G9: 2023-07-09 | H9: Paid Ads | I9: 252 | J9: 1 | K9: 10956 | L9: 4 | M9: 4 | N9: 4 | O9: 444 | P9: Champions | Q9: 1 | R9: Cluster C - Low Value
A10: CUST00009 | B10: Maya Dugal | C10: Female | D10: 27 | E10: Chandigarh | F10: Chandigarh | G10: 2024-06-25 | H10: Email Campaign | I10: 83 | J10: 4 | K10: 69595.7 | L10: 3 | M10: 2 | N10: 3 | O10: 323 | P10: Needs Attention | Q10: 0 | R10: Cluster B - Mid Value
A11: CUST00010 | B11: Om Chaudry | C11: Male | D11: 36 | E11: Nagpur | F11: Maharashtra | G11: 2025-02-14 | H11: Organic Search | I11: 153 | J11: 2 | K11: 19116.1 | L11: 4 | M11: 3 | N11: 4 | O11: 434 | P11: Loyal Customers | Q11: 1 | R11: Cluster C - Low Value
A12: CUST00011 | B12: Sachi Chatterjee | C12: Female | D12: 27 | E12: Lucknow | F12: Uttar Pradesh | G12: 2024-01-29 | H12: Referral | I12: 34 | J12: 7 | K12: 173734.75 | L12: 2 | M12: 1 | N12: 1 | O12: 211 | P12: Lost / Churned | Q12: 0 | R12: Cluster A - High Value
A13: CUST00012 | B13: Orinder Lalla | C13: Male | D13: 27 | E13: Delhi | F13: Delhi | G13: 2024-08-15 | H13: App | I13: 64 | J13: 12 | K13: 255072.55 | L13: 2 | M13: 1 | N13: 1 | O13: 211 | P13: Lost / Churned | Q13: 0 | R13: Cluster A - High Value
... A1201: CUST01200 | B1201: Yashawini Singh | C1201: Female | D1201: 44 | E1201: Kolkata | F1201: West Bengal | G1201: 2023-08-05 | H1201: Referral | I1201: 32 | J1201: 1 | K1201: 315 | L1201: 2 | M1201: 5 | N1201: 5 | O1201: 255 | P1201: At Risk | Q1201: 0 | R1201: Cluster C - Low Value
